[2024-12-01T03:58:53.417+0000] {taskinstance.py:1979} INFO - Dependencies all met for dep_context=non-requeueable deps ti=<TaskInstance: create_directory_in_blob.create_directory manual__2024-12-01T03:58:52.113920+00:00 [queued]>
[2024-12-01T03:58:53.421+0000] {taskinstance.py:1979} INFO - Dependencies all met for dep_context=requeueable deps ti=<TaskInstance: create_directory_in_blob.create_directory manual__2024-12-01T03:58:52.113920+00:00 [queued]>
[2024-12-01T03:58:53.421+0000] {taskinstance.py:2193} INFO - Starting attempt 1 of 1
[2024-12-01T03:58:53.427+0000] {taskinstance.py:2217} INFO - Executing <Task(PythonOperator): create_directory> on 2024-12-01 03:58:52.113920+00:00
[2024-12-01T03:58:53.429+0000] {standard_task_runner.py:60} INFO - Started process 3065 to run task
[2024-12-01T03:58:53.432+0000] {standard_task_runner.py:87} INFO - Running: ['***', 'tasks', 'run', 'create_directory_in_blob', 'create_directory', 'manual__2024-12-01T03:58:52.113920+00:00', '--job-id', '6679', '--raw', '--subdir', 'DAGS_FOLDER/create_blob_directory.py', '--cfg-path', '/tmp/tmp06j615_k']
[2024-12-01T03:58:53.433+0000] {standard_task_runner.py:88} INFO - Job 6679: Subtask create_directory
[2024-12-01T03:58:53.460+0000] {task_command.py:423} INFO - Running <TaskInstance: create_directory_in_blob.create_directory manual__2024-12-01T03:58:52.113920+00:00 [running]> on host 4f673f93eb11
[2024-12-01T03:58:53.499+0000] {taskinstance.py:2513} INFO - Exporting env vars: AIRFLOW_CTX_DAG_OWNER='***' AIRFLOW_CTX_DAG_ID='create_directory_in_blob' AIRFLOW_CTX_TASK_ID='create_directory' AIRFLOW_CTX_EXECUTION_DATE='2024-12-01T03:58:52.113920+00:00' AIRFLOW_CTX_TRY_NUMBER='1' AIRFLOW_CTX_DAG_RUN_ID='manual__2024-12-01T03:58:52.113920+00:00'
[2024-12-01T03:58:53.503+0000] {_universal.py:514} INFO - Request URL: 'https://***lab2024san.blob.core.windows.net/bd656-container/komsan/'
Request method: 'PUT'
Request headers:
    'x-ms-blob-type': 'REDACTED'
    'Content-Length': '0'
    'If-None-Match': '*'
    'x-ms-version': 'REDACTED'
    'Content-Type': 'application/octet-stream'
    'Accept': 'application/xml'
    'User-Agent': 'azsdk-python-storage-blob/12.19.1 Python/3.8.18 (Linux-6.10.14-linuxkit-aarch64-with-glibc2.34)'
    'x-ms-date': 'REDACTED'
    'x-ms-client-request-id': '949db66a-af98-11ef-8b26-0242ac120006'
    'Authorization': 'REDACTED'
No body was attached to the request
[2024-12-01T03:58:54.716+0000] {_universal.py:550} INFO - Response status: 409
Response headers:
    'Content-Length': '220'
    'Content-Type': 'application/xml'
    'Server': 'Windows-Azure-Blob/1.0 Microsoft-HTTPAPI/2.0'
    'x-ms-request-id': '100c30a9-f01e-00f3-6ea5-4381fe000000'
    'x-ms-client-request-id': '949db66a-af98-11ef-8b26-0242ac120006'
    'x-ms-version': 'REDACTED'
    'x-ms-error-code': 'BlobAlreadyExists'
    'Date': 'Sun, 01 Dec 2024 03:58:54 GMT'
[2024-12-01T03:58:54.726+0000] {taskinstance.py:2731} ERROR - Task failed with exception
Traceback (most recent call last):
  File "/home/airflow/.local/lib/python3.8/site-packages/airflow/models/taskinstance.py", line 444, in _execute_task
    result = _execute_callable(context=context, **execute_callable_kwargs)
  File "/home/airflow/.local/lib/python3.8/site-packages/airflow/models/taskinstance.py", line 414, in _execute_callable
    return execute_callable(context=context, **execute_callable_kwargs)
  File "/home/airflow/.local/lib/python3.8/site-packages/airflow/operators/python.py", line 200, in execute
    return_value = self.execute_callable()
  File "/home/airflow/.local/lib/python3.8/site-packages/airflow/operators/python.py", line 217, in execute_callable
    return self.python_callable(*self.op_args, **self.op_kwargs)
  File "/opt/airflow/dags/create_blob_directory.py", line 26, in create_directory_in_blob
    container_client.upload_blob(blob_name, b"")  # Empty content to simulate a directory
  File "/home/airflow/.local/lib/python3.8/site-packages/azure/core/tracing/decorator.py", line 78, in wrapper_use_tracer
    return func(*args, **kwargs)
  File "/home/airflow/.local/lib/python3.8/site-packages/azure/storage/blob/_container_client.py", line 1101, in upload_blob
    blob.upload_blob(
  File "/home/airflow/.local/lib/python3.8/site-packages/azure/core/tracing/decorator.py", line 78, in wrapper_use_tracer
    return func(*args, **kwargs)
  File "/home/airflow/.local/lib/python3.8/site-packages/azure/storage/blob/_blob_client.py", line 765, in upload_blob
    return upload_block_blob(**options)
  File "/home/airflow/.local/lib/python3.8/site-packages/azure/storage/blob/_upload_helpers.py", line 195, in upload_block_blob
    process_storage_error(error)
  File "/home/airflow/.local/lib/python3.8/site-packages/azure/storage/blob/_shared/response_handlers.py", line 184, in process_storage_error
    exec("raise error from None")   # pylint: disable=exec-used # nosec
  File "<string>", line 1, in <module>
  File "/home/airflow/.local/lib/python3.8/site-packages/azure/storage/blob/_upload_helpers.py", line 105, in upload_block_blob
    response = client.upload(
  File "/home/airflow/.local/lib/python3.8/site-packages/azure/core/tracing/decorator.py", line 78, in wrapper_use_tracer
    return func(*args, **kwargs)
  File "/home/airflow/.local/lib/python3.8/site-packages/azure/storage/blob/_generated/operations/_block_blob_operations.py", line 864, in upload
    map_error(status_code=response.status_code, response=response, error_map=error_map)
  File "/home/airflow/.local/lib/python3.8/site-packages/azure/core/exceptions.py", line 164, in map_error
    raise error
azure.core.exceptions.ResourceExistsError: The specified blob already exists.
RequestId:100c30a9-f01e-00f3-6ea5-4381fe000000
Time:2024-12-01T03:58:54.5440607Z
ErrorCode:BlobAlreadyExists
Content: <?xml version="1.0" encoding="utf-8"?><Error><Code>BlobAlreadyExists</Code><Message>The specified blob already exists.
RequestId:100c30a9-f01e-00f3-6ea5-4381fe000000
Time:2024-12-01T03:58:54.5440607Z</Message></Error>
[2024-12-01T03:58:54.742+0000] {taskinstance.py:1149} INFO - Marking task as FAILED. dag_id=create_directory_in_blob, task_id=create_directory, execution_date=20241201T035852, start_date=20241201T035853, end_date=20241201T035854
[2024-12-01T03:58:54.753+0000] {standard_task_runner.py:107} ERROR - Failed to execute job 6679 for task create_directory (The specified blob already exists.
RequestId:100c30a9-f01e-00f3-6ea5-4381fe000000
Time:2024-12-01T03:58:54.5440607Z
ErrorCode:BlobAlreadyExists
Content: <?xml version="1.0" encoding="utf-8"?><Error><Code>BlobAlreadyExists</Code><Message>The specified blob already exists.
RequestId:100c30a9-f01e-00f3-6ea5-4381fe000000
Time:2024-12-01T03:58:54.5440607Z</Message></Error>; 3065)
[2024-12-01T03:58:54.761+0000] {local_task_job_runner.py:234} INFO - Task exited with return code 1
[2024-12-01T03:58:54.777+0000] {taskinstance.py:3312} INFO - 0 downstream tasks scheduled from follow-on schedule check
